{
  "id": "CVE-2019-18348",
  "definition_id": "oval:com.ubuntu.focal:def:2019183480000000",
  "title": "CVE-2019-18348 on Ubuntu 20.04 LTS (focal) - medium.",
  "description": "An issue was discovered in urllib2 in Python 2.x through 2.7.17 and urllib in Python 3.x through 3.8.0. CRLF injection is possible if the attacker controls a url parameter, as demonstrated by the first argument to urllib.request.urlopen with \\r\\n (specifically in the host component of a URL) followed by an HTTP header. This is similar to the CVE-2019-9740 query string issue and the CVE-2019-9947 path string issue. (This is not exploitable when glibc has CVE-2016-10739 fixed.). This is fixed in: v2.7.18, v2.7.18rc1; v3.5.10, v3.5.10rc1; v3.6.11, v3.6.11rc1, v3.6.12; v3.7.8, v3.7.8rc1, v3.7.9; v3.8.3, v3.8.3rc1, v3.8.4, v3.8.4rc1, v3.8.5, v3.8.6, v3.8.6rc1.\n\nUpdate Instructions:\n\nRun `sudo ua fix CVE-2019-18348` to fix the vulnerability. The problem can be corrected\nby updating your system to the following package versions:\n\nidle-python2.7 - 2.7.18~rc1-2\nlibpython2.7 - 2.7.18~rc1-2\nlibpython2.7-minimal - 2.7.18~rc1-2\nlibpython2.7-stdlib - 2.7.18~rc1-2\nlibpython2.7-testsuite - 2.7.18~rc1-2\npython2.7 - 2.7.18~rc1-2\npython2.7-examples - 2.7.18~rc1-2\npython2.7-minimal - 2.7.18~rc1-2\nNo subscription required\n\nidle-python3.8 - 3.8.2-1ubuntu1.1\nlibpython3.8 - 3.8.2-1ubuntu1.1\nlibpython3.8-minimal - 3.8.2-1ubuntu1.1\nlibpython3.8-stdlib - 3.8.2-1ubuntu1.1\nlibpython3.8-testsuite - 3.8.2-1ubuntu1.1\npython3.8 - 3.8.2-1ubuntu1.1\npython3.8-examples - 3.8.2-1ubuntu1.1\npython3.8-full - 3.8.2-1ubuntu1.1\npython3.8-minimal - 3.8.2-1ubuntu1.1\npython3.8-venv - 3.8.2-1ubuntu1.1\nNo subscription required",
  "note": "leosilva\u003e This issue can be reproducible only in systems with the glibc issue mentioned in CVE-2016-10739 not fixed.",
  "severity": "Medium",
  "affected": {
    "family": "unix",
    "platform": "Ubuntu 20.04 LTS"
  },
  "packages": [
    {
      "name": "python2.7",
      "status": "not-affected",
      "note": "2.7.18~rc1-2"
    },
    {
      "name": "python3.8",
      "status": "released",
      "fixed_version": "0:3.8.2-1ubuntu1.1",
      "note": "3.8.2-1ubuntu1.1"
    }
  ],
  "references": [
    {
      "id": "CVE-2019-18348",
      "source": "CVE",
      "url": "https://cve.mitre.org/cgi-bin/cvename.cgi?name=CVE-2019-18348"
    },
    {
      "id": "",
      "source": "REF",
      "url": "https://ubuntu.com/security/CVE-2019-18348"
    },
    {
      "id": "",
      "source": "REF",
      "url": "https://ubuntu.com/security/notices/USN-4333-1"
    },
    {
      "id": "",
      "source": "REF",
      "url": "https://ubuntu.com/security/notices/USN-4333-2"
    },
    {
      "id": "",
      "source": "BUG",
      "url": "https://bugs.python.org/issue30458#msg347282"
    },
    {
      "id": "",
      "source": "BUG",
      "url": "https://bugs.python.org/issue38576"
    },
    {
      "id": "",
      "source": "BUG",
      "url": "https://bugzilla.redhat.com/show_bug.cgi?id=1727276"
    }
  ],
  "public_date": "2019-10-23T17:15:00Z",
  "public_date_at_usn": "2019-10-23T17:15:00Z",
  "assigned_to": "leosilva",
  "rights": "Copyright (C) 2019 Canonical Ltd."
}
