{
  "id": "CVE-2019-8906",
  "definition_id": "oval:org.opensuse.security:def:20198906",
  "title": "CVE-2019-8906",
  "description": "\n    do_core_note in readelf.c in libmagic.a in file 5.35 has an out-of-bounds read because memcpy is misused.\n    ",
  "severity": "Moderate",
  "affected": {
    "family": "unix",
    "platforms": [
      "openSUSE Leap 15.0"
    ]
  },
  "packages": [
    {
      "name": "file",
      "status": "released",
      "fixed_version": "0:5.32-lp150.6.3",
      "platform": "openSUSE Leap 15.0"
    },
    {
      "name": "file-devel",
      "status": "released",
      "fixed_version": "0:5.32-lp150.6.3",
      "platform": "openSUSE Leap 15.0"
    },
    {
      "name": "file-devel-32bit",
      "status": "released",
      "fixed_version": "0:5.32-lp150.6.3",
      "platform": "openSUSE Leap 15.0"
    },
    {
      "name": "file-magic",
      "status": "released",
      "fixed_version": "0:5.32-lp150.6.3",
      "platform": "openSUSE Leap 15.0"
    },
    {
      "name": "libmagic1",
      "status": "released",
      "fixed_version": "0:5.32-lp150.6.3",
      "platform": "openSUSE Leap 15.0"
    },
    {
      "name": "libmagic1-32bit",
      "status": "released",
      "fixed_version": "0:5.32-lp150.6.3",
      "platform": "openSUSE Leap 15.0"
    },
    {
      "name": "python-magic",
      "status": "released",
      "fixed_version": "0:5.32-lp150.6.3",
      "platform": "openSUSE Leap 15.0"
    },
    {
      "name": "python2-magic",
      "status": "released",
      "fixed_version": "0:5.32-lp150.6.3",
      "platform": "openSUSE Leap 15.0"
    },
    {
      "name": "python3-magic",
      "status": "released",
      "fixed_version": "0:5.32-lp150.6.3",
      "platform": "openSUSE Leap 15.0"
    }
  ],
  "references": [
    {
      "id": "CVE-2019-8906",
      "source": "CVE",
      "url": "http://cve.mitre.org/cgi-bin/cvename.cgi?name=CVE-2019-8906"
    },
    {
      "id": "SUSE bug 1126119",
      "source": "BUG",
      "url": "https://bugzilla.suse.com/1126119"
    }
  ]
}
