{
  "id": "CVE-2019-16865",
  "definition_id": "oval:com.ubuntu.xenial:def:2019168650000000",
  "title": "CVE-2019-16865 on Ubuntu 16.04 LTS (xenial) - low.",
  "description": "An issue was discovered in Pillow before 6.2.0. When reading specially crafted invalid image files, the library can either allocate very large amounts of memory or take an extremely long period of time to process the image.\n\nUpdate Instructions:\n\nRun `sudo ua fix CVE-2019-16865` to fix the vulnerability. The problem can be corrected\nby updating your system to the following package versions:\n\npython-imaging - 3.1.2-0ubuntu1.3\npython-pil - 3.1.2-0ubuntu1.3\npython-pil.imagetk - 3.1.2-0ubuntu1.3\npython3-pil - 3.1.2-0ubuntu1.3\npython3-pil.imagetk - 3.1.2-0ubuntu1.3\nNo subscription required",
  "note": "",
  "severity": "Low",
  "affected": {
    "family": "unix",
    "platform": "Ubuntu 16.04 LTS"
  },
  "packages": [
    {
      "name": "pillow",
      "status": "released",
      "fixed_version": "0:3.1.2-0ubuntu1.3",
      "note": "3.1.2-0ubuntu1.3"
    }
  ],
  "references": [
    {
      "id": "CVE-2019-16865",
      "source": "CVE",
      "url": "https://cve.mitre.org/cgi-bin/cvename.cgi?name=CVE-2019-16865"
    },
    {
      "id": "",
      "source": "REF",
      "url": "https://ubuntu.com/security/CVE-2019-16865"
    },
    {
      "id": "",
      "source": "REF",
      "url": "https://pillow.readthedocs.io/en/latest/releasenotes/6.2.0.html"
    },
    {
      "id": "",
      "source": "REF",
      "url": "https://ubuntu.com/security/notices/USN-4272-1"
    },
    {
      "id": "",
      "source": "BUG",
      "url": "https://github.com/python-pillow/Pillow/issues/4123"
    }
  ],
  "public_date": "2019-10-04T22:15:00Z",
  "public_date_at_usn": "2019-10-04T22:15:00Z",
  "rights": "Copyright (C) 2019 Canonical Ltd."
}
