{
  "id": "CVE-2016-9013",
  "definition_id": "oval:com.ubuntu.xenial:def:201690130000000",
  "title": "CVE-2016-9013 on Ubuntu 16.04 LTS (xenial) - medium.",
  "description": "Django 1.8.x before 1.8.16, 1.9.x before 1.9.11, and 1.10.x before 1.10.3 use a hardcoded password for a temporary database user created when running tests with an Oracle database, which makes it easier for remote attackers to obtain access to the database server by leveraging failure to manually specify a password in the database settings TEST dictionary.\n\nUpdate Instructions:\n\nRun `sudo ua fix CVE-2016-9013` to fix the vulnerability. The problem can be corrected\nby updating your system to the following package versions:\n\npython-django - 1.8.7-1ubuntu5.4\npython-django-common - 1.8.7-1ubuntu5.4\npython3-django - 1.8.7-1ubuntu5.4\nNo subscription required",
  "note": "",
  "severity": "Medium",
  "affected": {
    "family": "unix",
    "platform": "Ubuntu 16.04 LTS"
  },
  "packages": [
    {
      "name": "python-django",
      "status": "released",
      "fixed_version": "0:1.8.7-1ubuntu5.4",
      "note": "1.8.7-1ubuntu5.4"
    }
  ],
  "references": [
    {
      "id": "CVE-2016-9013",
      "source": "CVE",
      "url": "https://cve.mitre.org/cgi-bin/cvename.cgi?name=CVE-2016-9013"
    },
    {
      "id": "",
      "source": "REF",
      "url": "https://ubuntu.com/security/CVE-2016-9013"
    },
    {
      "id": "",
      "source": "REF",
      "url": "https://www.djangoproject.com/weblog/2016/nov/01/security-releases/"
    },
    {
      "id": "",
      "source": "REF",
      "url": "https://ubuntu.com/security/notices/USN-3115-1"
    }
  ],
  "public_date": "2016-11-01T00:00:00Z",
  "public_date_at_usn": "2016-11-01T00:00:00Z",
  "assigned_to": "mdeslaur",
  "discovered_by": "Marti Raudsepp",
  "rights": "Copyright (C) 2016 Canonical Ltd."
}
