{
  "vid": "b51cfaea-e919-11ec-9fba-080027240888",
  "topic": "py-numpy -- Missing return-value validation of the function PyArray_DescrNew",
  "description": "\n\t\u003cp\u003eNumpy reports:\u003c/p\u003e\n\t\u003cblockquote cite=\"https://github.com/numpy/numpy/pull/20960\"\u003e\n\t  \u003cp\u003eAt most call-sites for PyArray_DescrNew, there are no validations of its return,\n\t    but an invalid address may be returned.\u003c/p\u003e\n\t\u003c/blockquote\u003e\n      ",
  "affects": [
    {
      "name": "py38-numpy",
      "range": [
        {
          "lt": "1.22.4"
        }
      ]
    },
    {
      "name": "py39-numpy",
      "range": [
        {
          "lt": "1.22.4"
        }
      ]
    },
    {
      "name": "py310-numpy",
      "range": [
        {
          "lt": "1.22.4"
        }
      ]
    }
  ],
  "dates": {
    "discovery": "2021-05-19T00:00:00Z",
    "entry": "2022-06-11T00:00:00Z"
  },
  "references": [
    {
      "source": "URL",
      "text": "https://github.com/numpy/numpy/pull/20960"
    },
    {
      "source": "CVE",
      "text": "CVE-2021-41495"
    }
  ]
}
