{
  "id": "CVE-2021-4189",
  "definition_id": "oval:org.debian:def:120587166755635814818779097125025808355",
  "title": "CVE-2021-4189 python3.9",
  "description": "",
  "affected": {
    "family": "unix",
    "platform": "Debian GNU/Linux 11",
    "product": "python3.9"
  },
  "package": {
    "name": "python3.9",
    "fixed_version": "0:0"
  },
  "references": [
    {
      "id": "CVE-2021-4189",
      "source": "CVE",
      "url": "https://cve.mitre.org/cgi-bin/cvename.cgi?name=CVE-2021-4189"
    }
  ]
}
